Workbook

Sheet Index
A1: DCF Valuation
A2: Sheet index
A4: # | B4: Worksheet
A5: 1 | B5: 1.Input -->
A6: =A5+1 -> 2 | B6: P&L assumptions
A7: =A6+1 -> 3 | B7: BS assumptions
A8: =A7+1 -> 4 | B8: 2.Output -->
A9: =A8+1 -> 5 | B9: P&L
A10: =A9+1 -> 6 | B10: BS
A11: =A10+1 -> 7 | B11: Cash Flow
A12: =A11+1 -> 8 | B12: DCF valuation
A20: Color key for forecast formulas (BS / Cash flow / DCF valuation tabs):
A21: Black text = formula referencing only cells within the same sheet
A22: Green text = formula linking to another sheet
A24: Footnote:

Sheet P&L source
B1: P&L source
B3: USD in thousands | D3: 2018 Act | E3: 2019 Act | F3: 2020 Act
B4: Revenue from sales and services | D4: 177203 | E4: 188618 | F4: 208366
B5: Other revenue | D5: 3520 | E5: 2416 | F5: 2585
B6: Revenue | D6: 180723 | E6: 191034 | F6: 210951
B8: Raw materials | D8: -139903 | E8: -138923 | F8: -150080
B9: Direct costs | D9: -2491 | E9: -11649 | F9: -7443
B10: Cost for services | D10: -16390 | E10: -17878 | F10: -22293
B11: Lease costs | D11: -291 | E11: -246 | F11: -121
B12: Other operating expenses | D12: -1331 | E12: -1123 | F12: -1453
B14: EBITDA | D14: 20317 | E14: 21214 | F14: 29561
B16: D&A | D16: -2908 | E16: -4650 | F16: -6431
B18: EBIT | D18: 17410 | E18: 16564 | F18: 23130
B20: Financial income/expenses | D20: -1266 | E20: -2191 | F20: -2664
... B27: Net Income | D27: 12020 | E27: 10459 | F27: 16331

Sheet BS source
B1: BS source
B3: USD in thousands | D3: 31Dec18 Act | E3: 31Dec19 Act | F3: 31Dec20 Act | H3: USD in thousands | J3: 31Dec18 Act | K3: 31Dec19 Act | L3: 31Dec20 Act
B4: Intangible assets | D4: 5962 | E4: 5840 | F4: 5650 | H4: Share Capital | J4: 6785 | K4: 6800 | L4: 7508
B5: PP&E | D5: 45106 | E5: 49072 | F5: 56109 | H5: Reserves | J5: 46224 | K5: 44414 | L5: 46513
B6: Financial assets | D6: 8824 | E6: 9831 | F6: 10323 | H6: Retained earnings | J6: 16394 | K6: 25994 | L6: 21516
H7: Profit/(loss) for the year | J7: 12020 | K7: 10459 | L7: 16331
B8: Fixed assets | D8: 59892 | E8: 64743 | F8: 72082 | H8: Total Equity | J8: 81422 | K8: 87667 | L8: 91868
B10: Inventory | D10: 31167 | E10: 36397 | F10: 46212 | H10: Trade payable | J10: 15891 | K10: 26352 | L10: 36190
B11: Trade receivables | D11: 32884 | E11: 38556 | F11: 43582 | H11: Other liabilities | J11: 5315 | K11: 4334 | L11: 6473
B12: Other assets | D12: 8842 | E12: 11359 | F12: 17603 | H12: Deferred taxes | J12: 479 | K12: 1218 | L12: 1760
H13: Provisions for retirement benefits | J13: 175 | K13: 248 | L13: 240
B14: Cash and equivalents | D14: 11791 | E14: 19409 | F14: 8174
B15: Non fixed assets | D15: 84684 | E15: 105721 | F15: 115570 | H15: Bank borrowings | J15: 37403 | K15: 45595 | L15: 50680
H16: Other Financial liabilities | J16: 3890 | K16: 5051 | L16: 440
H17: Total Liabilities | J17: 63153 | K17: 82797 | L17: 95784
B19: Total Assets | D19: 144576 | E19: 170464 | F19: 187652 | H19: Total Liabilities & Equity | J19: 144576 | K19: 170464 | L19: 187652

Sheet P&L assumptions
A1: P&L assumptions
F2: Scenarios:
F3: Case 1: | G3: Optimistic case
F4: Case 2: | G4: Base case
A5: Selected case | B5: 2 | F5: Case 3: | G5: Worst case
A8: $ in thousands | B8: FY18 Actual | C8: FY19 Actual | D8: FY20 Actual | F8: FY21 Forecast | G8: FY22 Forecast | H8: FY23 Forecast | I8: FY24 Forecast | J8: FY25 Forecast
A9: Revenues | B9: 177203 | C9: 188618 | D9: 208366 | F9: =D9*(1+F10) -> 225035.28 | G9: =F9*(1+G10) -> 243038.1 | H9: =G9*(1+H10) -> 262481.15 | I9: =H9*(1+I10) -> 283479.64 | J9: =I9*(1+J10) -> 306158.01
A10: y-o-y growth% | C10: 0.064 | D10: 0.105 | F10: =CHOOSE($B$5,F11,F12,F13) -> 0.08 | G10: 0.08 | H10: 0.08 | I10: 0.08 | J10: 0.08
A11: Case 1: | F11: 0.1 | G11: 0.1 | H11: 0.1 | I11: 0.1 | J11: 0.1
A12: Case 2: | F12: 0.08 | G12: 0.08 | H12: 0.08 | I12: 0.08 | J12: 0.08
A13: Case 3: | F13: 0.06 | G13: 0.06 | H13: 0.06 | I13: 0.06 | J13: 0.06
A15: Other revenues | B15: 3520 | C15: 2416 | D15: 2585 | F15: 2585 | G15: 2585 | H15: 2585 | I15: 2585 | J15: 2585
A16: y-o-y growth % | F16: 0 | G16: 0 | H16: 0 | I16: 0 | J16: 0
A17: Case 1 | F17: 0 | G17: 0 | H17: 0 | I17: 0 | J17: 0
A18: Case 2 | F18: 0 | G18: 0 | H18: 0 | I18: 0 | J18: 0
A19: Case 3 | F19: 0 | G19: 0 | H19: 0 | I19: 0 | J19: 0
A21: Cost of goods sold | B21: -142394 | C21: -150572 | D21: -157523 | F21: -176694 | G21: -187296 | H21: -198534 | I21: -210446 | J21: -223073
A22: % of revenues | B22: -0.8 | C22: -0.8 | D22: -0.76 | F22: =CHOOSE($B$5,F23,F24,F25) -> -0.78 | G22: =CHOOSE($B$5,G23,G24,G25) -> -0.78 | H22: =CHOOSE($B$5,H23,H24,H25) -> -0.78 | I22: =CHOOSE($B$5,I23,I24,I25) -> -0.78 | J22: =CHOOSE($B$5,J23,J24,J25) -> -0.78
A23: Case 1 | F23: -0.76 | G23: -0.76 | H23: -0.76 | I23: -0.76 | J23: -0.76
A24: Case 2 | F24: -0.78 | G24: -0.78 | H24: -0.78 | I24: -0.78 | J24: -0.78
A25: Case 3 | F25: -0.8 | G25: -0.8 | H25: -0.8 | I25: -0.8 | J25: -0.8
A27: Operating expenses | B27: -18011 | C27: -19248 | D27: -23867 | F27: -24295 | G27: -25753 | H27: -27298 | I27: -28936 | J27: -30672
A28: % of revenues | B28: -0.1 | C28: -0.1 | D28: -0.11 | F28: =CHOOSE($B$5,F29,F30,F31) -> -0.11 | G28: =CHOOSE($B$5,G29,G30,G31) -> -0.11 | H28: =CHOOSE($B$5,H29,H30,H31) -> -0.11 | I28: =CHOOSE($B$5,I29,I30,I31) -> -0.11 | J28: =CHOOSE($B$5,J29,J30,J31) -> -0.11
A29: Case 1 | F29: -0.1 | G29: -0.1 | H29: -0.1 | I29: -0.1 | J29: -0.1
A30: Case 2 | F30: -0.11 | G30: -0.11 | H30: -0.11 | I30: -0.11 | J30: -0.11
A31: Case 3 | F31: -0.11 | G31: -0.11 | H31: -0.11 | I31: -0.11 | J31: -0.11
A33: D&A | B33: -2908 | C33: -4650 | D33: -6431 | F33: -6626 | G33: -7024 | H33: -7445 | I33: -7892 | J33: -8365
A34: % of revenues | B34: -0.02 | C34: -0.02 | D34: -0.03 | F34: =CHOOSE($B$5,F35,F36,F37) -> -0.03 | G34: =CHOOSE($B$5,G35,G36,G37) -> -0.03 | H34: =CHOOSE($B$5,H35,H36,H37) -> -0.03 | I34: =CHOOSE($B$5,I35,I36,I37) -> -0.03 | J34: =CHOOSE($B$5,J35,J36,J37) -> -0.03
A35: Case 1 | F35: -0.02 | G35: -0.02 | H35: -0.02 | I35: -0.02 | J35: -0.02
A36: Case 2 | F36: -0.03 | G36: -0.03 | H36: -0.03 | I36: -0.03 | J36: -0.03
A37: Case 3 | F37: -0.03 | G37: -0.03 | H37: -0.03 | I37: -0.03 | J37: -0.03
A39: Interest expense | B39: -1266 | C39: -2191 | D39: -2664 | F39: -2664 | G39: -2664 | H39: -2664 | I39: -2664 | J39: -2664
A40: y-o-y growth % | F40: =CHOOSE($B$5,F41,F42,F43) -> 0 | G40: =CHOOSE($B$5,G41,G42,G43) -> 0 | H40: =CHOOSE($B$5,H41,H42,H43) -> 0 | I40: =CHOOSE($B$5,I41,I42,I43) -> 0 | J40: =CHOOSE($B$5,J41,J42,J43) -> 0
A41: Case 1 | F41: 0 | G41: 0 | H41: 0 | I41: 0 | J41: 0
A42: Case 2 | F42: 0 | G42: 0 | H42: 0 | I42: 0 | J42: 0
A43: Case 3 | F43: 0 | G43: 0 | H43: 0 | I43: 0 | J43: 0
A45: Extraordinary income | B45: -318 | C45: -864 | D45: -320 | F45: - | G45: - | H45: - | I45: - | J45: -
A46: y-o-y growth % | C46: 1.722 | D46: -0.629 | F46: =CHOOSE($B$5,F47,F48,F49) -> 0 | G46: =CHOOSE($B$5,G47,G48,G49) -> 0 | H46: =CHOOSE($B$5,H47,H48,H49) -> 0 | I46: =CHOOSE($B$5,I47,I48,I49) -> 0 | J46: =CHOOSE($B$5,J47,J48,J49) -> 0
A47: Case 1 | F47: 0 | G47: 0 | H47: 0 | I47: 0 | J47: 0
A48: Case 2 | F48: 0 | G48: 0 | H48: 0 | I48: 0 | J48: 0
...

Sheet BS assumptions
B1: BS assumptions
B4: $ in thousands | C4: 31Dec18 Actual | D4: 31Dec19 Actual | E4: 31Dec20 Actual | G4: 31Dec21 Forecast | H4: 31Dec22 Forecast | I4: 31Dec23 Forecast | J4: 31Dec24 Forecast | K4: 31Dec25 Forecast
B5: Trade receivable | C5: 32884 | D5: 38556 | E5: 43582 | G5: =(G6*'P&L assumptions'!F9)/365 -> 46486.74 | H5: =(H6*'P&L assumptions'!G9)/365 -> 50205.679 | I5: =(I6*'P&L assumptions'!H9)/365 -> 54222.134 | J5: =(J6*'P&L assumptions'!I9)/365 -> 58559.904 | K5: =(K6*'P&L assumptions'!J9)/365 -> 63244.697
B6: Days receivable | C6: 66.4 | D6: 73.7 | E6: 75.4 | G6: 75.4 | H6: 75.4 | I6: 75.4 | J6: 75.4 | K6: 75.4
B8: Inventory | C8: 31167 | D8: 36397 | E8: 46212 | G8: =-(G9*'P&L assumptions'!F21)/365 -> 51836.133 | H8: =-(H9*'P&L assumptions'!G21)/365 -> 54946.406 | I8: =-(I9*'P&L assumptions'!H21)/365 -> 58243.261 | J8: =-(J9*'P&L assumptions'!I21)/365 -> 61737.845 | K8: =-(K9*'P&L assumptions'!J21)/365 -> 65442.186
B9: Days Inventory | C9: =-(C8/'P&L assumptions'!B21)*365 -> 79.890691 | D9: =-(D8/'P&L assumptions'!C21)*365 -> 88.229585 | E9: =-(E8/'P&L assumptions'!D21)*365 -> 107.07884 | G9: =$E$9 -> 107.07884 | H9: =$E$9 -> 107.07884 | I9: =$E$9 -> 107.07884 | J9: =$E$9 -> 107.07884 | K9: =$E$9 -> 107.07884
B11: Trade payable | C11: 15891 | D11: 26352 | E11: 36190 | G11: =-(G12*'P&L assumptions'!F21)/365 -> 40594.427 | H11: =-(H12*'P&L assumptions'!G21)/365 -> 43030.175 | I11: =-(I12*'P&L assumptions'!H21)/365 -> 45612.041 | J11: =-(J12*'P&L assumptions'!I21)/365 -> 48348.754 | K11: =-(K12*'P&L assumptions'!J21)/365 -> 51249.734
B12: Days payable | C12: =-(C11/'P&L assumptions'!B21)*365 -> 40.733563 | D12: =-(D11/'P&L assumptions'!C21)*365 -> 63.879606 | E12: =-(E11/'P&L assumptions'!D21)*365 -> 83.856643 | G12: =$E$12 -> 83.856643 | H12: =$E$12 -> 83.856643 | I12: =$E$12 -> 83.856643 | J12: =$E$12 -> 83.856643 | K12: =$E$12 -> 83.856643
B14: PP&E | C14: 45106 | D14: 49072 | E14: 56109 | G14: =G15*'P&L assumptions'!F9 -> 58808.563 | H14: =H15*'P&L assumptions'!G9 -> 63513.249 | I14: =I15*'P&L assumptions'!H9 -> 68594.308 | J14: =J15*'P&L assumptions'!I9 -> 74081.853 | K14: =K15*'P&L assumptions'!J9 -> 80008.401
B15: as a % of revenue | C15: =C14/'P&L assumptions'!B9 -> 0.25454422 | D15: =D14/'P&L assumptions'!C9 -> 0.26016605 | E15: =E14/'P&L assumptions'!D9 -> 0.26928098 | G15: =AVERAGE($C$15:$E$15) -> 0.26133042 | H15: =AVERAGE($C$15:$E$15) -> 0.26133042 | I15: =AVERAGE($C$15:$E$15) -> 0.26133042 | J15: =AVERAGE($C$15:$E$15) -> 0.26133042 | K15: =AVERAGE($C$15:$E$15) -> 0.26133042
B17: Other assets | C17: 8842 | D17: 11359 | E17: 17602 | G17: =G18*'P&L assumptions'!F9 -> 14597.002 | H17: =H18*'P&L assumptions'!G9 -> 15764.762 | I17: =I18*'P&L assumptions'!H9 -> 17025.943 | J17: =J18*'P&L assumptions'!I9 -> 18388.018 | K17: =K18*'P&L assumptions'!J9 -> 19859.06
B18: as a % of revenue | C18: =C17/'P&L assumptions'!B9 -> 0.049897575 | D18: =D17/'P&L assumptions'!C9 -> 0.060222248 | E18: =E17/'P&L assumptions'!D9 -> 0.084476354 | G18: =AVERAGE($C$18:$E$18) -> 0.064865392 | H18: =AVERAGE($C$18:$E$18) -> 0.064865392 | I18: =AVERAGE($C$18:$E$18) -> 0.064865392 | J18: =AVERAGE($C$18:$E$18) -> 0.064865392 | K18: =AVERAGE($C$18:$E$18) -> 0.064865392
B20: Other liabilities | C20: 5969 | D20: 5800 | E20: 8474 | G20: =G21*'P&L assumptions'!F9 -> 7883.9862 | H20: =H21*'P&L assumptions'!G9 -> 8514.7051 | I20: =I21*'P&L assumptions'!H9 -> 9195.8815 | J20: =J21*'P&L assumptions'!I9 -> 9931.552 | K20: =K21*'P&L assumptions'!J9 -> 10726.076
B21: as a % of revenue | C21: =C20/'P&L assumptions'!B9 -> 0.033684531 | D21: =D20/'P&L assumptions'!C9 -> 0.030749981 | E21: =E20/'P&L assumptions'!D9 -> 0.040668823 | G21: =AVERAGE($C$21:$E$21) -> 0.035034445 | H21: =AVERAGE($C$21:$E$21) -> 0.035034445 | I21: =AVERAGE($C$21:$E$21) -> 0.035034445 | J21: =AVERAGE($C$21:$E$21) -> 0.035034445 | K21: =AVERAGE($C$21:$E$21) -> 0.035034445

Sheet BS
B1: Balance Sheet
B3: $ in thousands | C3: 31Dec18 Actual | D3: 31Dec19 Actual | E3: 31Dec20 Actual | G3: 31Dec21 Forecast | H3: 31Dec22 Forecast | I3: 31Dec23 Forecast | J3: 31Dec24 Forecast | K3: 31Dec25 Forecast | M3: Note
B4: Intangible assets | C4: ='BS source'!D4 -> 5962 | D4: ='BS source'!E4 -> 5840 | E4: ='BS source'!F4 -> 5650 | G4: =E4 -> 5650 | H4: =G4 -> 5650 | I4: =H4 -> 5650 | J4: =I4 -> 5650 | K4: =J4 -> 5650 | M4: Flat
B5: PP&E | C5: =SUMIF('BS assumptions'!$B:$B,BS!$B5,'BS assumptions'!C:C) -> 45106 | D5: =SUMIF('BS assumptions'!$B:$B,BS!$B5,'BS assumptions'!D:D) -> 49072 | E5: =SUMIF('BS assumptions'!$B:$B,BS!$B5,'BS assumptions'!E:E) -> 56109 | G5: =SUMIF('BS assumptions'!$B:$B,BS!$B5,'BS assumptions'!G:G) -> 58808.563 | H5: =SUMIF('BS assumptions'!$B:$B,BS!$B5,'BS assumptions'!H:H) -> 63513.249 | I5: =SUMIF('BS assumptions'!$B:$B,BS!$B5,'BS assumptions'!I:I) -> 68594.308 | J5: =SUMIF('BS assumptions'!$B:$B,BS!$B5,'BS assumptions'!J:J) -> 74081.853 | K5: =SUMIF('BS assumptions'!$B:$B,BS!$B5,'BS assumptions'!K:K) -> 80008.401
B6: Financial assets | C6: ='BS source'!D6 -> 8824 | D6: ='BS source'!E6 -> 9831 | E6: ='BS source'!F6 -> 10323 | G6: =E6 -> 10323 | H6: =G6 -> 10323 | I6: =H6 -> 10323 | J6: =I6 -> 10323 | K6: =J6 -> 10323 | M6: Flat
B8: Inventory | C8: =SUMIF('BS assumptions'!$B:$B,BS!$B8,'BS assumptions'!C:C) -> 31167 | D8: =SUMIF('BS assumptions'!$B:$B,BS!$B8,'BS assumptions'!D:D) -> 36397 | E8: =SUMIF('BS assumptions'!$B:$B,BS!$B8,'BS assumptions'!E:E) -> 46212 | G8: =SUMIF('BS assumptions'!$B:$B,BS!$B8,'BS assumptions'!G:G) -> 51836.133 | H8: =SUMIF('BS assumptions'!$B:$B,BS!$B8,'BS assumptions'!H:H) -> 54946.406 | I8: =SUMIF('BS assumptions'!$B:$B,BS!$B8,'BS assumptions'!I:I) -> 58243.261 | J8: =SUMIF('BS assumptions'!$B:$B,BS!$B8,'BS assumptions'!J:J) -> 61737.845 | K8: =SUMIF('BS assumptions'!$B:$B,BS!$B8,'BS assumptions'!K:K) -> 65442.186
B9: Trade receivable | C9: =SUMIF('BS assumptions'!$B:$B,BS!$B9,'BS assumptions'!C:C) -> 32884 | D9: =SUMIF('BS assumptions'!$B:$B,BS!$B9,'BS assumptions'!D:D) -> 38556 | E9: =SUMIF('BS assumptions'!$B:$B,BS!$B9,'BS assumptions'!E:E) -> 43582 | G9: =SUMIF('BS assumptions'!$B:$B,BS!$B9,'BS assumptions'!G:G) -> 46486.74 | H9: =SUMIF('BS assumptions'!$B:$B,BS!$B9,'BS assumptions'!H:H) -> 50205.679 | I9: =SUMIF('BS assumptions'!$B:$B,BS!$B9,'BS assumptions'!I:I) -> 54222.134 | J9: =SUMIF('BS assumptions'!$B:$B,BS!$B9,'BS assumptions'!J:J) -> 58559.904 | K9: =SUMIF('BS assumptions'!$B:$B,BS!$B9,'BS assumptions'!K:K) -> 63244.697
B10: Other assets | C10: =SUMIF('BS assumptions'!$B:$B,BS!$B10,'BS assumptions'!C:C) -> 8842 | D10: =SUMIF('BS assumptions'!$B:$B,BS!$B10,'BS assumptions'!D:D) -> 11359 | E10: =SUMIF('BS assumptions'!$B:$B,BS!$B10,'BS assumptions'!E:E) -> 17602 | G10: =SUMIF('BS assumptions'!$B:$B,BS!$B10,'BS assumptions'!G:G) -> 14597.002 | H10: =SUMIF('BS assumptions'!$B:$B,BS!$B10,'BS assumptions'!H:H) -> 15764.762 | I10: =SUMIF('BS assumptions'!$B:$B,BS!$B10,'BS assumptions'!I:I) -> 17025.943 | J10: =SUMIF('BS assumptions'!$B:$B,BS!$B10,'BS assumptions'!J:J) -> 18388.018 | K10: =SUMIF('BS assumptions'!$B:$B,BS!$B10,'BS assumptions'!K:K) -> 19859.06
B12: Cash and equivalents | C12: ='BS source'!D14 -> 11791 | D12: ='BS source'!E14 -> 19409 | E12: ='BS source'!F14 -> 8174 | G12: ='Cash flow'!G32 -> 17637.999 | H12: ='Cash flow'!H32 -> 26311.69 | I12: ='Cash flow'!I32 -> 39219.303 | J12: ='Cash flow'!J32 -> 56911.026 | K12: ='Cash flow'!K32 -> 79995.018
B14: Total Assets | C14: 144576 | D14: 170464 | E14: 187652 | G14: =SUM(G4,G5,G6,G8,G9,G10,G12) -> 205339.44 | H14: =SUM(H4,H5,H6,H8,H9,H10,H12) -> 226714.79 | I14: =SUM(I4,I5,I6,I8,I9,I10,I12) -> 253277.95 | J14: =SUM(J4,J5,J6,J8,J9,J10,J12) -> 285651.65 | K14: =SUM(K4,K5,K6,K8,K9,K10,K12) -> 324522.36
B16: Trade payable | C16: =SUMIF('BS assumptions'!$B:$B,BS!$B16,'BS assumptions'!C:C) -> 15891 | D16: =SUMIF('BS assumptions'!$B:$B,BS!$B16,'BS assumptions'!D:D) -> 26352 | E16: =SUMIF('BS assumptions'!$B:$B,BS!$B16,'BS assumptions'!E:E) -> 36190 | G16: =SUMIF('BS assumptions'!$B:$B,BS!$B16,'BS assumptions'!G:G) -> 40594.427 | H16: =SUMIF('BS assumptions'!$B:$B,BS!$B16,'BS assumptions'!H:H) -> 43030.175 | I16: =SUMIF('BS assumptions'!$B:$B,BS!$B16,'BS assumptions'!I:I) -> 45612.041 | J16: =SUMIF('BS assumptions'!$B:$B,BS!$B16,'BS assumptions'!J:J) -> 48348.754 | K16: =SUMIF('BS assumptions'!$B:$B,BS!$B16,'BS assumptions'!K:K) -> 51249.734
B17: Other liabilities | C17: =SUMIF('BS assumptions'!$B:$B,BS!$B17,'BS assumptions'!C:C) -> 5969 | D17: =SUMIF('BS assumptions'!$B:$B,BS!$B17,'BS assumptions'!D:D) -> 5800 | E17: =SUMIF('BS assumptions'!$B:$B,BS!$B17,'BS assumptions'!E:E) -> 8474 | G17: =SUMIF('BS assumptions'!$B:$B,BS!$B17,'BS assumptions'!G:G) -> 7883.9862 | H17: =SUMIF('BS assumptions'!$B:$B,BS!$B17,'BS assumptions'!H:H) -> 8514.7051 | I17: =SUMIF('BS assumptions'!$B:$B,BS!$B17,'BS assumptions'!I:I) -> 9195.8815 | J17: =SUMIF('BS assumptions'!$B:$B,BS!$B17,'BS assumptions'!J:J) -> 9931.552 | K17: =SUMIF('BS assumptions'!$B:$B,BS!$B17,'BS assumptions'!K:K) -> 10726.076
B19: Financial liabilities | C19: ='BS source'!J15+'BS source'!J16 -> 41293 | D19: ='BS source'!K15+'BS source'!K16 -> 50646 | E19: ='BS source'!L15+'BS source'!L16 -> 51120 | G19: =E19 -> 51120 | H19: =G19 -> 51120 | I19: =H19 -> 51120 | J19: =I19 -> 51120 | K19: =J19 -> 51120 | M19: Flat
B21: Shareholders' equity | C21: ='BS source'!J8 -> 81422 | D21: ='BS source'!K8 -> 87667 | E21: ='BS source'!L8 -> 91868 | G21: =E21+'P&L'!F19 -> 105741.02 | H21: =G21+'P&L'!G19 -> 124049.91 | I21: =H21+'P&L'!H19 -> 147350.03 | J21: =I21+'P&L'!I19 -> 176251.34 | K21: =J21+'P&L'!J19 -> 211426.55
B23: Total Liabilities & Equities | C23: 144576 | D23: 170464 | E23: 187652 | F23: - | G23: =SUM(G16,G17,G19,G21) -> 205339.44 | H23: =SUM(H16,H17,H19,H21) -> 226714.79 | I23: =SUM(I16,I17,I19,I21) -> 253277.95 | J23: =SUM(J16,J17,J19,J21) -> 285651.65 | K23: =SUM(K16,K17,K19,K21) -> 324522.36
B25: Check | C25: 0 | D25: - | E25: 0 | G25: =G14-G23 -> 0 | H25: =H14-H23 -> 0 | I25: =I14-I23 -> 0 | J25: =J14-J23 -> 0 | K25: =K14-K23 -> 0

Sheet P&L
A1: P&L
A3: $ in thousands | B3: FY18 Actual | C3: FY19 Actual | D3: FY20 Actual | F3: FY21 Forecast | G3: FY22 Forecast | H3: FY23 Forecast | I3: FY24 Forecast | J3: FY25 Forecast
A4: Revenues | B4: =SUMIF('P&L assumptions'!$A:$A,'P&L'!$A4,'P&L assumptions'!B:B) -> 177203 | C4: =SUMIF('P&L assumptions'!$A:$A,'P&L'!$A4,'P&L assumptions'!C:C) -> 188618 | D4: =SUMIF('P&L assumptions'!$A:$A,'P&L'!$A4,'P&L assumptions'!D:D) -> 208366 | E4: - | F4: =SUMIF('P&L assumptions'!$A:$A,'P&L'!$A4,'P&L assumptions'!F:F) -> 225035.28 | G4: =SUMIF('P&L assumptions'!$A:$A,'P&L'!$A4,'P&L assumptions'!G:G) -> 243038.1 | H4: =SUMIF('P&L assumptions'!$A:$A,'P&L'!$A4,'P&L assumptions'!H:H) -> 262481.15 | I4: =SUMIF('P&L assumptions'!$A:$A,'P&L'!$A4,'P&L assumptions'!I:I) -> 283479.64 | J4: =SUMIF('P&L assumptions'!$A:$A,'P&L'!$A4,'P&L assumptions'!J:J) -> 306158.01
A5: Other revenues | B5: =SUMIF('P&L assumptions'!$A:$A,'P&L'!$A5,'P&L assumptions'!B:B) -> 3520 | C5: =SUMIF('P&L assumptions'!$A:$A,'P&L'!$A5,'P&L assumptions'!C:C) -> 2416 | D5: =SUMIF('P&L assumptions'!$A:$A,'P&L'!$A5,'P&L assumptions'!D:D) -> 2585 | E5: - | F5: 2585 | G5: 2585 | H5: 2585 | I5: 2585 | J5: 2585
A6: Total revenues | B6: =B4+B5 -> 180723 | C6: =C4+C5 -> 191034 | D6: =D4+D5 -> 210951 | F6: =F4+F5 -> 227620.28 | G6: =G4+G5 -> 245623.1 | H6: =H4+H5 -> 265066.15 | I6: =I4+I5 -> 286064.64 | J6: =J4+J5 -> 308743.01
A7: Cost of goods sold | B7: =SUMIF('P&L assumptions'!$A:$A,'P&L'!$A7,'P&L assumptions'!B:B) -> -142394 | C7: =SUMIF('P&L assumptions'!$A:$A,'P&L'!$A7,'P&L assumptions'!C:C) -> -150572 | D7: =SUMIF('P&L assumptions'!$A:$A,'P&L'!$A7,'P&L assumptions'!D:D) -> -157523 | E7: - | F7: =SUMIF('P&L assumptions'!$A:$A,'P&L'!$A7,'P&L assumptions'!F:F) -> -176694 | G7: =SUMIF('P&L assumptions'!$A:$A,'P&L'!$A7,'P&L assumptions'!G:G) -> -187296 | H7: =SUMIF('P&L assumptions'!$A:$A,'P&L'!$A7,'P&L assumptions'!H:H) -> -198534 | I7: =SUMIF('P&L assumptions'!$A:$A,'P&L'!$A7,'P&L assumptions'!I:I) -> -210446 | J7: =SUMIF('P&L assumptions'!$A:$A,'P&L'!$A7,'P&L assumptions'!J:J) -> -223073
A8: Gross margin | B8: =B6+B7 -> 38329 | C8: =C6+C7 -> 40462 | D8: =D6+D7 -> 53428 | F8: =F6+F7 -> 50926.28 | G8: =G6+G7 -> 58327.102 | H8: =H6+H7 -> 66532.151 | I8: =I6+I7 -> 75618.643 | J8: =J6+J7 -> 85670.014
A9: Operating expenses | B9: =SUMIF('P&L assumptions'!$A:$A,'P&L'!$A9,'P&L assumptions'!B:B) -> -18011 | C9: =SUMIF('P&L assumptions'!$A:$A,'P&L'!$A9,'P&L assumptions'!C:C) -> -19248 | D9: =SUMIF('P&L assumptions'!$A:$A,'P&L'!$A9,'P&L assumptions'!D:D) -> -23867 | E9: - | F9: =SUMIF('P&L assumptions'!$A:$A,'P&L'!$A9,'P&L assumptions'!F:F) -> -24295 | G9: =SUMIF('P&L assumptions'!$A:$A,'P&L'!$A9,'P&L assumptions'!G:G) -> -25753 | H9: =SUMIF('P&L assumptions'!$A:$A,'P&L'!$A9,'P&L assumptions'!H:H) -> -27298 | I9: =SUMIF('P&L assumptions'!$A:$A,'P&L'!$A9,'P&L assumptions'!I:I) -> -28936 | J9: =SUMIF('P&L assumptions'!$A:$A,'P&L'!$A9,'P&L assumptions'!J:J) -> -30672
A10: EBITDA | B10: =B8+B9 -> 20318 | C10: =C8+C9 -> 21214 | D10: =D8+D9 -> 29561 | F10: =F8+F9 -> 26631.28 | G10: =G8+G9 -> 32574.102 | H10: =H8+H9 -> 39234.151 | I10: =I8+I9 -> 46682.643 | J10: =J8+J9 -> 54998.014
A11: D&A | B11: =SUMIF('P&L assumptions'!$A:$A,'P&L'!$A11,'P&L assumptions'!B:B) -> -2908 | C11: =SUMIF('P&L assumptions'!$A:$A,'P&L'!$A11,'P&L assumptions'!C:C) -> -4650 | D11: =SUMIF('P&L assumptions'!$A:$A,'P&L'!$A11,'P&L assumptions'!D:D) -> -6431 | E11: - | F11: =SUMIF('P&L assumptions'!$A:$A,'P&L'!$A11,'P&L assumptions'!F:F) -> -6626 | G11: =SUMIF('P&L assumptions'!$A:$A,'P&L'!$A11,'P&L assumptions'!G:G) -> -7024 | H11: =SUMIF('P&L assumptions'!$A:$A,'P&L'!$A11,'P&L assumptions'!H:H) -> -7445 | I11: =SUMIF('P&L assumptions'!$A:$A,'P&L'!$A11,'P&L assumptions'!I:I) -> -7892 | J11: =SUMIF('P&L assumptions'!$A:$A,'P&L'!$A11,'P&L assumptions'!J:J) -> -8365
A12: EBIT | B12: =B10+B11 -> 17410 | C12: =C10+C11 -> 16564 | D12: =D10+D11 -> 23130 | F12: =F10+F11 -> 20005.28 | G12: =G10+G11 -> 25550.102 | H12: =H10+H11 -> 31789.151 | I12: =I10+I11 -> 38790.643 | J12: =J10+J11 -> 46633.014
A13: Interest expense | B13: =SUMIF('P&L assumptions'!$A:$A,'P&L'!$A13,'P&L assumptions'!B:B) -> -1266 | C13: =SUMIF('P&L assumptions'!$A:$A,'P&L'!$A13,'P&L assumptions'!C:C) -> -2191 | D13: =SUMIF('P&L assumptions'!$A:$A,'P&L'!$A13,'P&L assumptions'!D:D) -> -2664 | E13: - | F13: =SUMIF('P&L assumptions'!$A:$A,'P&L'!$A13,'P&L assumptions'!F:F) -> -2664 | G13: =SUMIF('P&L assumptions'!$A:$A,'P&L'!$A13,'P&L assumptions'!G:G) -> -2664 | H13: =SUMIF('P&L assumptions'!$A:$A,'P&L'!$A13,'P&L assumptions'!H:H) -> -2664 | I13: =SUMIF('P&L assumptions'!$A:$A,'P&L'!$A13,'P&L assumptions'!I:I) -> -2664 | J13: =SUMIF('P&L assumptions'!$A:$A,'P&L'!$A13,'P&L assumptions'!J:J) -> -2664
A14: Extraordinary income | B14: =SUMIF('P&L assumptions'!$A:$A,'P&L'!$A14,'P&L assumptions'!B:B) -> -318 | C14: =SUMIF('P&L assumptions'!$A:$A,'P&L'!$A14,'P&L assumptions'!C:C) -> -864 | D14: =SUMIF('P&L assumptions'!$A:$A,'P&L'!$A14,'P&L assumptions'!D:D) -> -320 | E14: - | F14: =SUMIF('P&L assumptions'!$A:$A,'P&L'!$A14,'P&L assumptions'!F:F) -> 0 | G14: =SUMIF('P&L assumptions'!$A:$A,'P&L'!$A14,'P&L assumptions'!G:G) -> 0 | H14: =SUMIF('P&L assumptions'!$A:$A,'P&L'!$A14,'P&L assumptions'!H:H) -> 0 | I14: =SUMIF('P&L assumptions'!$A:$A,'P&L'!$A14,'P&L assumptions'!I:I) -> 0 | J14: =SUMIF('P&L assumptions'!$A:$A,'P&L'!$A14,'P&L assumptions'!J:J) -> 0
A15: EBT | B15: =B12+B13+B14 -> 15826 | C15: =C12+C13+C14 -> 13509 | D15: =D12+D13+D14 -> 20146 | F15: =F12+F13+F14 -> 17341.28 | G15: =G12+G13+G14 -> 22886.102 | H15: =H12+H13+H14 -> 29125.151 | I15: =I12+I13+I14 -> 36126.643 | J15: =J12+J13+J14 -> 43969.014
A16: Tax rate | B16: =B17/B15 -> -0.24049033 | C16: =C17/C15 -> -0.22577541 | D16: =D17/D15 -> -0.18936762 | F16: ='P&L assumptions'!F52 -> -0.2 | G16: ='P&L assumptions'!G52 -> -0.2 | H16: ='P&L assumptions'!H52 -> -0.2 | I16: ='P&L assumptions'!I52 -> -0.2 | J16: ='P&L assumptions'!J52 -> -0.2
A17: Taxes | B17: =SUMIF('P&L assumptions'!$A:$A,'P&L'!$A17,'P&L assumptions'!B:B) -> -3806 | C17: =SUMIF('P&L assumptions'!$A:$A,'P&L'!$A17,'P&L assumptions'!C:C) -> -3050 | D17: =SUMIF('P&L assumptions'!$A:$A,'P&L'!$A17,'P&L assumptions'!D:D) -> -3815 | E17: - | F17: =F16*F15 -> -3468.256 | G17: =G16*G15 -> -4577.2205 | H17: =H16*H15 -> -5825.0301 | I17: =I16*I15 -> -7225.3285 | J17: =J16*J15 -> -8793.8028
A19: Net income | B19: =B17+B15 -> 12020 | C19: =C17+C15 -> 10459 | D19: =D17+D15 -> 16331 | E19: - | F19: =F17+F15 -> 13873.024 | G19: =G17+G15 -> 18308.882 | H19: =H17+H15 -> 23300.12 | I19: =I17+I15 -> 28901.314 | J19: =J17+J15 -> 35175.211

Sheet Cash flow
B1: Cash Flow
B3: $ in thousands | D3: FY19 Actual | E3: FY20 Actual | G3: FY21 Forecast | H3: FY22 Forecast | I3: FY23 Forecast | J3: FY24 Forecast | K3: FY25 Forecast
B4: EBIT | D4: 16564 | E4: 23130 | G4: ='P&L'!F12 -> 20005.28 | H4: ='P&L'!G12 -> 25550.102 | I4: ='P&L'!H12 -> 31789.151 | J4: ='P&L'!I12 -> 38790.643 | K4: ='P&L'!J12 -> 46633.014
B5: Operating taxes | D5: -3740 | E5: -4380 | G5: =G4*G6 -> -4001.056 | H5: =H4*H6 -> -5110.0205 | I5: =I4*I6 -> -6357.8301 | J5: =J4*J6 -> -7758.1285 | K5: =K4*K6 -> -9326.6028
B6: Operating tax rate | D6: -0.23 | E6: -0.19 | G6: ='P&L'!F16 -> -0.2 | H6: ='P&L'!G16 -> -0.2 | I6: ='P&L'!H16 -> -0.2 | J6: ='P&L'!I16 -> -0.2 | K6: ='P&L'!J16 -> -0.2
B7: NOPAT | D7: 12824 | E7: 18750 | G7: =G4+G5 -> 16004.224 | H7: =H4+H5 -> 20440.082 | I7: =I4+I5 -> 25431.32 | J7: =J4+J5 -> 31032.514 | K7: =K4+K5 -> 37306.411
B9: Add-back D&A | D9: 4650 | E9: 6431 | G9: =-'P&L'!F11 -> 6626 | H9: =-'P&L'!G11 -> 7024 | I9: =-'P&L'!H11 -> 7445 | J9: =-'P&L'!I11 -> 7892 | K9: =-'P&L'!J11 -> 8365
B10: Gross Cash Flow | D10: 17474 | E10: 25181 | G10: =G7+G9 -> 22630.224 | H10: =H7+H9 -> 27464.082 | I10: =I7+I9 -> 32876.32 | J10: =J7+J9 -> 38924.514 | K10: =K7+K9 -> 45671.411
B12: Inventory | D12: -5230 | E12: -9815 | G12: =-(BS!G8-BS!E8) -> -5624.1327 | H12: =-(BS!H8-BS!G8) -> -3110.2736 | I12: =-(BS!I8-BS!H8) -> -3296.8548 | J12: =-(BS!J8-BS!I8) -> -3494.5839 | K12: =-(BS!K8-BS!J8) -> -3704.3411
B13: Trade receivables | D13: -5672 | E13: -5026 | G13: =-(BS!G9-BS!E9) -> -2904.74 | H13: =-(BS!H9-BS!G9) -> -3718.9392 | I13: =-(BS!I9-BS!H9) -> -4016.4543 | J13: =-(BS!J9-BS!I9) -> -4337.7707 | K13: =-(BS!K9-BS!J9) -> -4684.7923
B14: Trade payables | D14: 10460 | E14: 9838 | G14: =BS!G16-BS!E16 -> 4404.4266 | H14: =BS!H16-BS!G16 -> 2435.7483 | I14: =BS!I16-BS!H16 -> 2581.8656 | J14: =BS!J16-BS!I16 -> 2736.7132 | K14: =BS!K16-BS!J16 -> 2900.9804
B15: Investments in working capital | D15: -442 | E15: -5003 | G15: =G12+G13+G14 -> -4124.4461 | H15: =H12+H13+H14 -> -4393.4645 | I15: =I12+I13+I14 -> -4731.4435 | J15: =J12+J13+J14 -> -5095.6414 | K15: =K12+K13+K14 -> -5488.1531
B16: Investments in other assets/liabilities | D16: -2686 | E16: -3571 | G16: =-(BS!G10-BS!E10)+(BS!G17-BS!E17) -> 2414.9845 | H16: =-(BS!H10-BS!G10)+(BS!H17-BS!G17) -> -537.04124 | I16: =-(BS!I10-BS!H10)+(BS!I17-BS!H17) -> -580.00454 | J16: =-(BS!J10-BS!I10)+(BS!J17-BS!I17) -> -626.40491 | K16: =-(BS!K10-BS!J10)+(BS!K17-BS!J17) -> -676.5173
B18: Capex | D18: -8616 | E18: -13467 | G18: =-(BS!G5-BS!E5)+'P&L'!F11 -> -9325.5635 | H18: =-(BS!H5-BS!G5)+'P&L'!G11 -> -11728.685 | I18: =-(BS!I5-BS!H5)+'P&L'!H11 -> -12526.06 | J18: =-(BS!J5-BS!I5)+'P&L'!I11 -> -13379.545 | K18: =-(BS!K5-BS!J5)+'P&L'!J11 -> -14291.548
B19: Other investments | D19: -885 | E19: -302 | G19: =-((BS!G4-BS!E4)+(BS!G6-BS!E6)) -> 0 | H19: =-((BS!H4-BS!G4)+(BS!H6-BS!G6)) -> 0 | I19: =-((BS!I4-BS!H4)+(BS!I6-BS!H6)) -> 0 | J19: =-((BS!J4-BS!I4)+(BS!J6-BS!I6)) -> 0 | K19: =-((BS!K4-BS!J4)+(BS!K6-BS!J6)) -> 0
B21: Extraordinary items | D21: -864 | E21: -320 | G21: ='P&L'!F14 -> 0 | H21: ='P&L'!G14 -> 0 | I21: ='P&L'!H14 -> 0 | J21: ='P&L'!I14 -> 0 | K21: ='P&L'!J14 -> 0
B23: UFCF | D23: 3981 | E23: 2518 | G23: =G10+G15+G16+G18+G19+G21 -> 11595.199 | H23: =H10+H15+H16+H18+H19+H21 -> 10804.891 | I23: =I10+I15+I16+I18+I19+I21 -> 15038.813 | J23: =J10+J15+J16+J18+J19+J21 -> 19822.923 | K23: =K10+K15+K16+K18+K19+K21 -> 25215.193
B25: Interest expenses | D25: -2191 | E25: -2664 | G25: ='P&L'!F13 -> -2664 | H25: ='P&L'!G13 -> -2664 | I25: ='P&L'!H13 -> -2664 | J25: ='P&L'!I13 -> -2664 | K25: ='P&L'!J13 -> -2664
B26: Delta Taxes vs. Operating taxes | D26: 690 | E26: 565 | G26: ='P&L'!F17-G5 -> 532.8 | H26: ='P&L'!G17-H5 -> 532.8 | I26: ='P&L'!H17-I5 -> 532.8 | J26: ='P&L'!I17-J5 -> 532.8 | K26: ='P&L'!J17-K5 -> 532.8
B27: Delta Financial liabilities | D27: 9352 | E27: 475 | G27: =BS!G19-BS!E19 -> 0 | H27: =BS!H19-BS!G19 -> 0 | I27: =BS!I19-BS!H19 -> 0 | J27: =BS!J19-BS!I19 -> 0 | K27: =BS!K19-BS!J19 -> 0
B28: Delta Equity (incl. dividends) | D28: -4214 | E28: -12130 | G28: =(BS!G21-BS!E21)-'P&L'!F19 -> 0 | H28: =(BS!H21-BS!G21)-'P&L'!G19 -> 0 | I28: =(BS!I21-BS!H21)-'P&L'!H19 -> 0 | J28: =(BS!J21-BS!I21)-'P&L'!I19 -> 0 | K28: =(BS!K21-BS!J21)-'P&L'!J19 -> 0
B29: Net Cash Flow | D29: 7618 | E29: -11235 | G29: =G23+G25+G26+G27+G28 -> 9463.9989 | H29: =H23+H25+H26+H27+H28 -> 8673.6911 | I29: =I23+I25+I26+I27+I28 -> 12907.613 | J29: =J23+J25+J26+J27+J28 -> 17691.723 | K29: =K23+K25+K26+K27+K28 -> 23083.993
B31: Opening cash | D31: 11791 | E31: 19409 | G31: =E32 -> 8174 | H31: =G32 -> 17637.999 | I31: =H32 -> 26311.69 | J31: =I32 -> 39219.303 | K31: =J32 -> 56911.026
B32: Closing cash | D32: 19409 | E32: 8174 | G32: =G31+G29 -> 17637.999 | H32: =H31+H29 -> 26311.69 | I32: =I31+I29 -> 39219.303 | J32: =J31+J29 -> 56911.026 | K32: =K31+K29 -> 79995.018
B34: Check | D34: 0 | E34: 0 | G34: =G32-BS!G12 -> 0 | H34: =H32-BS!H12 -> 0 | I34: =I32-BS!I12 -> 0 | J34: =J32-BS!J12 -> 0 | K34: =K32-BS!K12 -> 0

Sheet DCF valuation
A1: DCF Valuation
A4: WACC | B4: 0.1
A5: g | B5: 0.02
F6: 1 | G6: 2 | H6: 3 | I6: 4 | J6: 5
A7: $ in thousands | B7: FY18 Actual | C7: FY19 Actual | D7: FY20 Actual | F7: FY21 Forecast | G7: FY22 Forecast | H7: FY23 Forecast | I7: FY24 Forecast | J7: FY25 Forecast
A8: UFCF | C8: 3981 | D8: 2518 | F8: ='Cash flow'!G23 -> 11595.199 | G8: ='Cash flow'!H23 -> 10804.891 | H8: ='Cash flow'!I23 -> 15038.813 | I8: ='Cash flow'!J23 -> 19822.923 | J8: ='Cash flow'!K23 -> 25215.193
A10: Discount factor | F10: =1/(1+$B$4)^F6 -> 0.90909091 | G10: =1/(1+$B$4)^G6 -> 0.82644628 | H10: =1/(1+$B$4)^H6 -> 0.7513148 | I10: =1/(1+$B$4)^I6 -> 0.68301346 | J10: =1/(1+$B$4)^J6 -> 0.62092132
A11: Present value of UFCF | F11: =F8*F10 -> 10541.09 | G11: =G8*G10 -> 8929.6621 | H11: =H8*H10 -> 11298.882 | I11: =I8*I10 -> 13539.323 | J11: =J8*J10 -> 15656.651
A14: DCF Valuation
A15: PV of Cash flows | D15: =SUM(F11:J11) -> 59965.608
A16: Continuing value | D16: =J8*(1+B5)/(B4-B5) -> 321493.71
A17: PV of Continuing value | D17: =D16*J10 -> 199622.3
A18: Enterprise value | D18: =D15+D17 -> 259587.91
A19: () Financial liabilities | D19: =-BS!E19 -> -51120
A20: Cash | D20: =BS!E12 -> 8174
A21: Equity value | D21: =D18+D19+D20 -> 216641.91 | G21: 0.09 | H21: 0.1 | I21: 0.11 | J21: 0.12
F22: 0.01 | G22: =NPV(G$21,$F$8:$J$8)+($J$8*(1+$F22)/(G$21-$F22))/(1+G$21)^5+$D$19+$D$20 -> 225730.32 | H22: =NPV(H$21,$F$8:$J$8)+($J$8*(1+$F22)/(H$21-$F22))/(1+H$21)^5+$D$19+$D$20 -> 192722.02 | I22: =NPV(I$21,$F$8:$J$8)+($J$8*(1+$F22)/(I$21-$F22))/(1+I$21)^5+$D$19+$D$20 -> 166424.12 | J22: =NPV(J$21,$F$8:$J$8)+($J$8*(1+$F22)/(J$21-$F22))/(1+J$21)^5+$D$19+$D$20 -> 145001.79
F23: 0.02 | G23: =NPV(G$21,$F$8:$J$8)+($J$8*(1+$F23)/(G$21-$F23))/(1+G$21)^5+$D$19+$D$20 -> 257628.67 | H23: =NPV(H$21,$F$8:$J$8)+($J$8*(1+$F23)/(H$21-$F23))/(1+H$21)^5+$D$19+$D$20 -> 216641.91 | I23: =NPV(I$21,$F$8:$J$8)+($J$8*(1+$F23)/(I$21-$F23))/(1+I$21)^5+$D$19+$D$20 -> 184879.71 | J23: =NPV(J$21,$F$8:$J$8)+($J$8*(1+$F23)/(J$21-$F23))/(1+J$21)^5+$D$19+$D$20 -> 159569.71
F24: 0.03 | G24: =NPV(G$21,$F$8:$J$8)+($J$8*(1+$F24)/(G$21-$F24))/(1+G$21)^5+$D$19+$D$20 -> 300159.81 | H24: =NPV(H$21,$F$8:$J$8)+($J$8*(1+$F24)/(H$21-$F24))/(1+H$21)^5+$D$19+$D$20 -> 247396.04 | I24: =NPV(I$21,$F$8:$J$8)+($J$8*(1+$F24)/(I$21-$F24))/(1+I$21)^5+$D$19+$D$20 -> 207949.2 | J24: =NPV(J$21,$F$8:$J$8)+($J$8*(1+$F24)/(J$21-$F24))/(1+J$21)^5+$D$19+$D$20 -> 177374.95
F25: 0.04 | G25: =NPV(G$21,$F$8:$J$8)+($J$8*(1+$F25)/(G$21-$F25))/(1+G$21)^5+$D$19+$D$20 -> 359703.4 | H25: =NPV(H$21,$F$8:$J$8)+($J$8*(1+$F25)/(H$21-$F25))/(1+H$21)^5+$D$19+$D$20 -> 288401.55 | I25: =NPV(I$21,$F$8:$J$8)+($J$8*(1+$F25)/(I$21-$F25))/(1+I$21)^5+$D$19+$D$20 -> 237609.96 | J25: =NPV(J$21,$F$8:$J$8)+($J$8*(1+$F25)/(J$21-$F25))/(1+J$21)^5+$D$19+$D$20 -> 199631.49
